2025-04-21 17:07:11,747 - test_platform_services.PlatformServiceIntegrationTests.test_scenario_09_delete_user_owning_token - INFO - --- Starting test: test_scenario_09_delete_user_owning_token ---
2025-04-21 17:07:11,747 - test_platform_services.PlatformServiceIntegrationTests.test_scenario_09_delete_user_owning_token - INFO - Setting up Scenario 09...
2025-04-21 17:07:11,747 - test_platform_services.PlatformServiceIntegrationTests.test_scenario_09_delete_user_owning_token - DEBUG - Helper: Attempting to create user with email prefix testuser
2025-04-21 17:07:11,747 - test_platform_services.PlatformServiceIntegrationTests.test_scenario_09_delete_user_owning_token - ERROR - Helper _create_user failed: StatusCode.UNAVAILABLE - failed to connect to all addresses; last error: UNKNOWN: ipv4:127.0.0.1:5557: Failed to connect to remote host: connect: Connection refused (61)
Traceback (most recent call last):
  File "/Users/anil/workspace/projects/dex/test/test_platform_services.py", line 106, in _create_user
    resp = self.user_stub.CreateUser(req)
  File "/Users/anil/workspace/projects/dex/test/venv/lib/python3.13/site-packages/grpc/_channel.py", line 1181, in __call__
    return _end_unary_response_blocking(state, call, False, None)
  File "/Users/anil/workspace/projects/dex/test/venv/lib/python3.13/site-packages/grpc/_channel.py", line 1006, in _end_unary_response_blocking
    raise _InactiveRpcError(state)  # pytype: disable=not-instantiable
    ^^^^^^^^^^^^^^^^^^^^^^^^^^^^^^
grpc._channel._InactiveRpcError: <_InactiveRpcError of RPC that terminated with:
	status = StatusCode.UNAVAILABLE
	details = "failed to connect to all addresses; last error: UNKNOWN: ipv4:127.0.0.1:5557: Failed to connect to remote host: connect: Connection refused (61)"
	debug_error_string = "UNKNOWN:Error received from peer  {created_time:"2025-04-21T17:07:11.747811-04:00", grpc_status:14, grpc_message:"failed to connect to all addresses; last error: UNKNOWN: ipv4:127.0.0.1:5557: Failed to connect to remote host: connect: Connection refused (61)"}"
>
2025-04-21 17:07:11,748 - test_platform_services.PlatformServiceIntegrationTests.test_scenario_09_delete_user_owning_token - ERROR - Unexpected exception during test_scenario_09
Traceback (most recent call last):
  File "/Users/anil/workspace/projects/dex/test/test_platform_services.py", line 106, in _create_user
    resp = self.user_stub.CreateUser(req)
  File "/Users/anil/workspace/projects/dex/test/venv/lib/python3.13/site-packages/grpc/_channel.py", line 1181, in __call__
    return _end_unary_response_blocking(state, call, False, None)
  File "/Users/anil/workspace/projects/dex/test/venv/lib/python3.13/site-packages/grpc/_channel.py", line 1006, in _end_unary_response_blocking
    raise _InactiveRpcError(state)  # pytype: disable=not-instantiable
    ^^^^^^^^^^^^^^^^^^^^^^^^^^^^^^
grpc._channel._InactiveRpcError: <_InactiveRpcError of RPC that terminated with:
	status = StatusCode.UNAVAILABLE
	details = "failed to connect to all addresses; last error: UNKNOWN: ipv4:127.0.0.1:5557: Failed to connect to remote host: connect: Connection refused (61)"
	debug_error_string = "UNKNOWN:Error received from peer  {created_time:"2025-04-21T17:07:11.747811-04:00", grpc_status:14, grpc_message:"failed to connect to all addresses; last error: UNKNOWN: ipv4:127.0.0.1:5557: Failed to connect to remote host: connect: Connection refused (61)"}"
>

During handling of the above exception, another exception occurred:

Traceback (most recent call last):
  File "/Users/anil/workspace/projects/dex/test/test_platform_services.py", line 465, in test_scenario_09_delete_user_owning_token
    user = self._create_user()
  File "/Users/anil/workspace/projects/dex/test/test_platform_services.py", line 113, in _create_user
    self.fail(f"Helper _create_user failed unexpectedly: {e.code()} - {e.details()}")
    ~~~~~~~~~^^^^^^^^^^^^^^^^^^^^^^^^^^^^^^^^^^^^^^^^^^^^^^^^^^^^^^^^^^^^^^^^^^^^^^^^
  File "/opt/homebrew/Cellar/python@3.13/3.13.2/Frameworks/Python.framework/Versions/3.13/lib/python3.13/unittest/case.py", line 732, in fail
    raise self.failureException(msg)
AssertionError: Helper _create_user failed unexpectedly: StatusCode.UNAVAILABLE - failed to connect to all addresses; last error: UNKNOWN: ipv4:127.0.0.1:5557: Failed to connect to remote host: connect: Connection refused (61)
2025-04-21 17:07:11,748 - test_platform_services.PlatformServiceIntegrationTests.test_scenario_09_delete_user_owning_token - INFO - Cleanup: Deleting remaining resources...
2025-04-21 17:07:11,748 - test_platform_services.PlatformServiceIntegrationTests.test_scenario_09_delete_user_owning_token - INFO - --- Finished test: test_scenario_09_delete_user_owning_token ---
