2025-04-21 17:07:11,750 - test_platform_services.PlatformServiceIntegrationTests.test_scenario_12_token_creation_with_non_existent_user - INFO - --- Starting test: test_scenario_12_token_creation_with_non_existent_user ---
2025-04-21 17:07:11,750 - test_platform_services.PlatformServiceIntegrationTests.test_scenario_12_token_creation_with_non_existent_user - INFO - Setting up Scenario 12...
2025-04-21 17:07:11,750 - test_platform_services.PlatformServiceIntegrationTests.test_scenario_12_token_creation_with_non_existent_user - DEBUG - Helper: Attempting to create role with title prefix TestRole for app example-app
2025-04-21 17:07:11,750 - test_platform_services.PlatformServiceIntegrationTests.test_scenario_12_token_creation_with_non_existent_user - ERROR - Helper _create_role failed: StatusCode.UNAVAILABLE - failed to connect to all addresses; last error: UNKNOWN: ipv4:127.0.0.1:5557: Failed to connect to remote host: connect: Connection refused (61)
Traceback (most recent call last):
  File "/Users/anil/workspace/projects/dex/test/test_platform_services.py", line 129, in _create_role
    resp = self.role_stub.CreatePlatformAppRole(req)
  File "/Users/anil/workspace/projects/dex/test/venv/lib/python3.13/site-packages/grpc/_channel.py", line 1181, in __call__
    return _end_unary_response_blocking(state, call, False, None)
  File "/Users/anil/workspace/projects/dex/test/venv/lib/python3.13/site-packages/grpc/_channel.py", line 1006, in _end_unary_response_blocking
    raise _InactiveRpcError(state)  # pytype: disable=not-instantiable
    ^^^^^^^^^^^^^^^^^^^^^^^^^^^^^^
grpc._channel._InactiveRpcError: <_InactiveRpcError of RPC that terminated with:
	status = StatusCode.UNAVAILABLE
	details = "failed to connect to all addresses; last error: UNKNOWN: ipv4:127.0.0.1:5557: Failed to connect to remote host: connect: Connection refused (61)"
	debug_error_string = "UNKNOWN:Error received from peer  {created_time:"2025-04-21T17:07:11.750482-04:00", grpc_status:14, grpc_message:"failed to connect to all addresses; last error: UNKNOWN: ipv4:127.0.0.1:5557: Failed to connect to remote host: connect: Connection refused (61)"}"
>
2025-04-21 17:07:11,750 - test_platform_services.PlatformServiceIntegrationTests.test_scenario_12_token_creation_with_non_existent_user - ERROR - Unexpected exception during test_scenario_12
Traceback (most recent call last):
  File "/Users/anil/workspace/projects/dex/test/test_platform_services.py", line 129, in _create_role
    resp = self.role_stub.CreatePlatformAppRole(req)
  File "/Users/anil/workspace/projects/dex/test/venv/lib/python3.13/site-packages/grpc/_channel.py", line 1181, in __call__
    return _end_unary_response_blocking(state, call, False, None)
  File "/Users/anil/workspace/projects/dex/test/venv/lib/python3.13/site-packages/grpc/_channel.py", line 1006, in _end_unary_response_blocking
    raise _InactiveRpcError(state)  # pytype: disable=not-instantiable
    ^^^^^^^^^^^^^^^^^^^^^^^^^^^^^^
grpc._channel._InactiveRpcError: <_InactiveRpcError of RPC that terminated with:
	status = StatusCode.UNAVAILABLE
	details = "failed to connect to all addresses; last error: UNKNOWN: ipv4:127.0.0.1:5557: Failed to connect to remote host: connect: Connection refused (61)"
	debug_error_string = "UNKNOWN:Error received from peer  {created_time:"2025-04-21T17:07:11.750482-04:00", grpc_status:14, grpc_message:"failed to connect to all addresses; last error: UNKNOWN: ipv4:127.0.0.1:5557: Failed to connect to remote host: connect: Connection refused (61)"}"
>

During handling of the above exception, another exception occurred:

Traceback (most recent call last):
  File "/Users/anil/workspace/projects/dex/test/test_platform_services.py", line 583, in test_scenario_12_token_creation_with_non_existent_user
    role = self._create_role()
  File "/Users/anil/workspace/projects/dex/test/test_platform_services.py", line 136, in _create_role
    self.fail(f"Helper _create_role failed unexpectedly: {e.code()} - {e.details()}")
    ~~~~~~~~~^^^^^^^^^^^^^^^^^^^^^^^^^^^^^^^^^^^^^^^^^^^^^^^^^^^^^^^^^^^^^^^^^^^^^^^^
  File "/opt/homebrew/Cellar/python@3.13/3.13.2/Frameworks/Python.framework/Versions/3.13/lib/python3.13/unittest/case.py", line 732, in fail
    raise self.failureException(msg)
AssertionError: Helper _create_role failed unexpectedly: StatusCode.UNAVAILABLE - failed to connect to all addresses; last error: UNKNOWN: ipv4:127.0.0.1:5557: Failed to connect to remote host: connect: Connection refused (61)
2025-04-21 17:07:11,751 - test_platform_services.PlatformServiceIntegrationTests.test_scenario_12_token_creation_with_non_existent_user - INFO - Cleanup: Deleting test resources...
2025-04-21 17:07:11,751 - test_platform_services.PlatformServiceIntegrationTests.test_scenario_12_token_creation_with_non_existent_user - INFO - --- Finished test: test_scenario_12_token_creation_with_non_existent_user ---
