2025-04-21 17:05:56,730 - test_platform_services.PlatformServiceIntegrationTests.test_scenario_05_assign_non_existent_role_to_user - INFO - --- Starting test: test_scenario_05_assign_non_existent_role_to_user ---
2025-04-21 17:05:56,730 - test_platform_services.PlatformServiceIntegrationTests.test_scenario_05_assign_non_existent_role_to_user - INFO - Setting up Scenario 05...
2025-04-21 17:05:56,730 - test_platform_services.PlatformServiceIntegrationTests.test_scenario_05_assign_non_existent_role_to_user - DEBUG - Helper: Attempting to create user with email prefix testuser
2025-04-21 17:07:11,738 - test_platform_services.PlatformServiceIntegrationTests.test_scenario_05_assign_non_existent_role_to_user - ERROR - Helper _create_user failed: StatusCode.INTERNAL - failed to create user
Traceback (most recent call last):
  File "/Users/anil/workspace/projects/dex/test/test_platform_services.py", line 106, in _create_user
    resp = self.user_stub.CreateUser(req)
  File "/Users/anil/workspace/projects/dex/test/venv/lib/python3.13/site-packages/grpc/_channel.py", line 1181, in __call__
    return _end_unary_response_blocking(state, call, False, None)
  File "/Users/anil/workspace/projects/dex/test/venv/lib/python3.13/site-packages/grpc/_channel.py", line 1006, in _end_unary_response_blocking
    raise _InactiveRpcError(state)  # pytype: disable=not-instantiable
    ^^^^^^^^^^^^^^^^^^^^^^^^^^^^^^
grpc._channel._InactiveRpcError: <_InactiveRpcError of RPC that terminated with:
	status = StatusCode.INTERNAL
	details = "failed to create user"
	debug_error_string = "UNKNOWN:Error received from peer  {grpc_message:"failed to create user", grpc_status:13, created_time:"2025-04-21T17:07:11.736707-04:00"}"
>
2025-04-21 17:07:11,740 - test_platform_services.PlatformServiceIntegrationTests.test_scenario_05_assign_non_existent_role_to_user - ERROR - Unexpected exception during test_scenario_05
Traceback (most recent call last):
  File "/Users/anil/workspace/projects/dex/test/test_platform_services.py", line 106, in _create_user
    resp = self.user_stub.CreateUser(req)
  File "/Users/anil/workspace/projects/dex/test/venv/lib/python3.13/site-packages/grpc/_channel.py", line 1181, in __call__
    return _end_unary_response_blocking(state, call, False, None)
  File "/Users/anil/workspace/projects/dex/test/venv/lib/python3.13/site-packages/grpc/_channel.py", line 1006, in _end_unary_response_blocking
    raise _InactiveRpcError(state)  # pytype: disable=not-instantiable
    ^^^^^^^^^^^^^^^^^^^^^^^^^^^^^^
grpc._channel._InactiveRpcError: <_InactiveRpcError of RPC that terminated with:
	status = StatusCode.INTERNAL
	details = "failed to create user"
	debug_error_string = "UNKNOWN:Error received from peer  {grpc_message:"failed to create user", grpc_status:13, created_time:"2025-04-21T17:07:11.736707-04:00"}"
>

During handling of the above exception, another exception occurred:

Traceback (most recent call last):
  File "/Users/anil/workspace/projects/dex/test/test_platform_services.py", line 282, in test_scenario_05_assign_non_existent_role_to_user
    user = self._create_user()
  File "/Users/anil/workspace/projects/dex/test/test_platform_services.py", line 113, in _create_user
    self.fail(f"Helper _create_user failed unexpectedly: {e.code()} - {e.details()}")
    ~~~~~~~~~^^^^^^^^^^^^^^^^^^^^^^^^^^^^^^^^^^^^^^^^^^^^^^^^^^^^^^^^^^^^^^^^^^^^^^^^
  File "/opt/homebrew/Cellar/python@3.13/3.13.2/Frameworks/Python.framework/Versions/3.13/lib/python3.13/unittest/case.py", line 732, in fail
    raise self.failureException(msg)
AssertionError: Helper _create_user failed unexpectedly: StatusCode.INTERNAL - failed to create user
2025-04-21 17:07:11,742 - test_platform_services.PlatformServiceIntegrationTests.test_scenario_05_assign_non_existent_role_to_user - INFO - --- Finished test: test_scenario_05_assign_non_existent_role_to_user ---
